<?xml version="1.0" ?>
<robot name="mini_mec" xmlns:xacro="http://www.ros.org/wiki/xacro">

    <!-- Include common properties and gazebo-specific configurations -->
    <xacro:include filename="common_properties.xacro"/>
    <xacro:include filename="mobile_base_gazebo.xacro"/>
    
    <!-- Base link definition -->
    <link name="base_link">
        <visual>
            <origin xyz=" 0 0 0.0975" rpy="0 0 0" />
            <geometry>
                <box size="0.27 0.185 0.055"/>
            </geometry>
            <material name="white">
                <color rgba="1 1 1 1"/>
            </material>
        </visual>
        <collision>
            <origin xyz=" 0 0 0.0975" rpy="0 0 0" />
            <geometry>
                <box size="0.27 0.185 0.055"/>
            </geometry>
        </collision>
        <xacro:box_inertia m="3.23" l="0.54" w="0.37" h="0.11" xyz="0 0 0.0975" rpy="0 0 0"/> <!-- l, w, h is 2x the value to fix inertia values-->
    </link>   
    <!-- Left wheel joint and link -->
    

    <link name="left_wheel_link">
        <visual>
            <origin xyz="0 0 0" rpy="0 0 0" />
            <geometry>
                <cylinder radius="0.0375" length = "0.03"/>
            </geometry>
            <material name="black">
                <color rgba="0 0 0 1"/>
            </material>
        </visual>
        <collision>
            <origin xyz="0 0 0" rpy="0 0 0" />
            <geometry>
                <cylinder radius="0.0375" length = "0.03"/>
            </geometry>
        </collision>
        <xacro:cylinder_inertia m="0.18" r="0.075" h="0.06" xyz="0 0 0" rpy="0 0 0"/> <!-- r, h is 2x the visual to fix inertia values-->
    </link>

    <joint name="left_wheel_joint" type="continuous">
        <origin xyz="-0.085 0.0975 0.0375" rpy="1.57 0 0"/>
        <parent link="base_link"/>
        <child link="left_wheel_link"/>
        <axis xyz="0 0 1"/>
    </joint>
    
    <joint name="right_wheel_joint" type="continuous">
        <origin xyz="-0.085 -0.0975 0.0375" rpy="1.57 0 0"/>
        <parent link="base_link"/>
        <child link="right_wheel_link"/>
        <axis xyz="0 0 1"/>
    </joint>

    <link name="right_wheel_link">
        <visual>
            <origin xyz="0 0 0" rpy="0 0 0" />
            <geometry>
                <cylinder radius="0.0375" length = "0.03"/>
            </geometry>
            <material name="black">
                <color rgba="0 0 0 1"/>
            </material>
        </visual>
        <collision>
            <origin xyz="0 0 0" rpy="0 0 0" />
            <geometry>
                <cylinder radius="0.0375" length = "0.03"/>
            </geometry>
        </collision>
        <xacro:cylinder_inertia m="0.18" r="0.075" h="0.06" xyz="0 0 0" rpy="0 0 0"/> <!-- r, h is 2x the visual to fix inertia values-->
    </link>

      <joint name="left_front_joint" type="continuous">
        <origin xyz="0.085 0.0975 0.0375" rpy="1.57 0 0"/>
        <parent link="base_link"/>
        <child link="left_front_link"/>
        <axis xyz="0 0 1"/>
    </joint>

    <link name="left_front_link">
        <visual>
            <origin xyz="0 0 0" rpy="0 0 0" />
            <geometry>
                <cylinder radius="0.0375" length = "0.03"/>
            </geometry>
            <material name="black">
                <color rgba="0 0 0 1"/>
            </material>
        </visual>
        <collision>
            <origin xyz="0 0 0" rpy="0 0 0" />
            <geometry>
                <cylinder radius="0.0375" length = "0.03"/>
            </geometry>
        </collision>
        <xacro:cylinder_inertia m="0.18" r="0.075" h="0.06" xyz="0 0 0" rpy="0 0 0"/> <!-- r, h is 2x the visual to fix inertia values-->
    </link>

    <joint name="right_front_joint" type="continuous">
        <origin xyz="0.085 -0.0975 0.0375" rpy="1.57 0 0"/>
        <parent link="base_link"/>
        <child link="right_front_link"/>
        <axis xyz="0 0 1"/>
    </joint>

    <link name="right_front_link">
        <visual>
            <origin xyz="0 0 0" rpy="0 0 0" />
            <geometry>
                <cylinder radius="0.0375" length = "0.03"/>
            </geometry>
            <material name="black">
                <color rgba="0 0 0 1"/>
            </material>
        </visual>
        <collision>
            <origin xyz="0 0 0" rpy="0 0 0" />
            <geometry>
                <cylinder radius="0.0375" length = "0.03"/>
            </geometry>
        </collision>
        <xacro:cylinder_inertia m="0.18" r="0.075" h="0.06" xyz="0 0 0" rpy="0 0 0"/> <!-- r, h is 2x the visual to fix inertia values-->
    </link>

    <link name="imu_link">
        <xacro:box_inertia m="0.005" l="0.005" w="0.005" h="0.005" xyz="0 0 0.0975" rpy="0 0 0"/>
        <visual>
            <origin xyz="0 0 0.0850" rpy="0 0 0"/>
            <geometry>
                <box size="0.005 0.005 0.005"/>
            </geometry>
            <material name="black">
                <color rgba="0 0 0 1"/>
            </material>
        </visual>
        <collision>
            <origin xyz="0 0 0.0850" rpy="0 0 0"/>
            <geometry>
                <box size="0.005 0.005 0.005"/>
            </geometry>
        </collision>
    </link>
    <joint name="imu_joint" type="fixed">
        <parent link="base_link"/>
        <child link="imu_link"/>
        <origin xyz="0 0 0.0425" rpy="0 0 0"/>
    </joint>
    <!--
    <link name="camera_link">
        <visual>
            <geometry>
                <box size="0.02 0.05 0.025"/>
            </geometry>
            <material name="grey"/>
            <collision>
                <geometry>
                    <box size="0.02 0.05 0.025"/>
                </geometry>
            </collision>
            <inertial>
                <xacro:box_inertia m="0.1" l="0.1" w="0.01" h="0.05" xyz="0 0 0" rpy="0 0 0"/>
            </inertial>
        </visual>
    </link>
    <joint name="base_camera_joint" type="fixed">
        <parent link="base_link"/>
        <child link="camera_link"/>
        <origin xyz="0.110 0 0.1    375" rpy=" 0 0 0"/>
        

    </joint>
    -->
    <link name="lidar_link">
        <visual>
            <origin xyz="0.035 0 0.0785" rpy="0 0 0"/>
            <geometry>
                <cylinder radius="0.035" length="0.065"/>
            </geometry>
            <material name="grey">
                <color rgba="0.5 0.5 0.5 1"/>
            </material>
        </visual>
        <collision>
            <origin xyz="0.035 0 0.0785" rpy="0 0 0"/>
            <geometry>
                <cylinder radius="0.035" length="0.065"/>
            </geometry>
        </collision>
        <inertial>
            <origin xyz="0.035 0 0.0785" rpy="0 0 0"/>
            <mass value="0.8"/>
            <inertia ixx="0.002" ixy="0" ixz="0" iyy="0.002" iyz="0" izz="0.002"/>
        </inertial>
    </link>

    <joint name="lidar_joint" type="fixed">
        <parent link="base_link"/>
        <child link="lidar_link"/>
        <origin xyz="0.035 0 0.0785" rpy="0 0 0"/>
    </joint>
</robot>
